Workbook

Sheet Summary_Dashboard
F2: PAYROLL DASHBOARD | لوحة الرواتب
F4: ="Elite Development · "&IF($K$5="All Months","All months",TEXT($K$5,"mmmm yyyy"))&" · "&$B$8&" riders" -> Elite Development · All months · 15 riders
I5: Month filter | الشهر ▸ | K5: All Months | M5: ◂ All Months or one month | Q5: Filter start | R5: =IF($K$5="All Months",1,$K$5) -> 1
Q6: Filter end (excl.) | R6: =IF($K$5="All Months",2958465,EDATE($K$5,1)) -> 2958465
B7: TOTAL RIDERS | عدد المندوبين | E7: TOTAL GROSS SALARY | إجمالي الراتب | H7: TOTAL DEDUCTIONS | الخصومات | K7: TOTAL FINAL SALARY | صافي الرواتب
B8: =COUNTIFS(Salary_Calculation[Salary Month],">="&Dash_Start,Salary_Calculation[Salary Month],"<"&Dash_End) -> 15 | E8: =SUMIFS(Salary_Calculation[Gross Salary Before Deductions],Salary_Calculation[Salary Month],">="&Dash_Start,Salary_Calculation[Salary Month],"<"&Dash_End) -> 17676.222 | H8: =SUMIFS(Salary_Calculation[Total Deductions],Salary_Calculation[Salary Month],">="&Dash_Start,Salary_Calculation[Salary Month],"<"&Dash_End) -> 4478.75 | K8: =SUMIFS(Salary_Calculation[Final Salary],Salary_Calculation[Salary Month],">="&Dash_Start,Salary_Calculation[Salary Month],"<"&Dash_End) -> 14208.35 | Q8: Chart data
B9: ="review required: "&COUNTIFS(Salary_Calculation[Payment Status],"Review Required",Salary_Calculation[Salary Month],">="&Dash_Start,Salary_Calculation[Salary Month],"<"&Dash_End) -> review required: 0 | E9: =IFERROR("avg SAR "&TEXT(E8/$B$8,"#,##0")&" per rider","") -> avg SAR 1,178 per rider | H9: =IFERROR(TEXT(H8/E8,"0.0%")&" of gross salary","") -> 25.3% of gross salary | K9: =IFERROR("avg SAR "&TEXT(K8/$B$8,"#,##0")&" per rider","") -> avg SAR 947 per rider | Q9: Gross | R9: =E8 -> 17676.222
Q10: Deductions | R10: =H8 -> 4478.75
B11: AMOUNT DUE FROM RIDERS | مستحق على المندوبين | E11: COMPLETED ORDERS | الطلبات المكتملة | H11: MISSING ORDERS | الطلبات الناقصة | K11: EXTRA ORDERS | الطلبات الإضافية | Q11: Final salary | R11: =K8 -> 14208.35
B12: =SUMIFS(Salary_Calculation[Total Amount Due from Rider],Salary_Calculation[Salary Month],">="&Dash_Start,Salary_Calculation[Salary Month],"<"&Dash_End) -> 1026.86 | E12: =SUMIFS(Salary_Calculation[Completed Orders],Salary_Calculation[Salary Month],">="&Dash_Start,Salary_Calculation[Salary Month],"<"&Dash_End) -> 4734 | H12: =SUMIFS(Salary_Calculation[Missing Orders],Salary_Calculation[Salary Month],">="&Dash_Start,Salary_Calculation[Salary Month],"<"&Dash_End) -> 586 | K12: =SUMIFS(Salary_Calculation[Extra Orders],Salary_Calculation[Salary Month],">="&Dash_Start,Salary_Calculation[Salary Month],"<"&Dash_End) -> 130 | Q12: Due from riders | R12: =B12 -> 1026.86
B13: =COUNTIFS(Salary_Calculation[Total Amount Due from Rider],">0",Salary_Calculation[Salary Month],">="&Dash_Start,Salary_Calculation[Salary Month],"<"&Dash_End)&" rider(s) owe the company" -> 4 rider(s) owe the company | E13: =IFERROR("avg "&TEXT(E12/$B$8,"#,##0")&" per rider","") -> avg 316 per rider | H13: =COUNTIFS(Salary_Calculation[Missing Orders],">0",Salary_Calculation[Salary Month],">="&Dash_Start,Salary_Calculation[Salary Month],"<"&Dash_End)&" rider(s) below target" -> 12 rider(s) below target | K13: =COUNTIFS(Salary_Calculation[Extra Orders],">0",Salary_Calculation[Salary Month],">="&Dash_Start,Salary_Calculation[Salary Month],"<"&Dash_End)&" rider(s) earned a bonus" -> 3 rider(s) earned a bonus
B15: =IF(COUNTIFS(Salary_Calculation[Payment Status],"Review Required",Salary_Calculation[Salary Month],">="&Dash_Start,Salary_Calculation[Salary Month],"<"&Dash_End)=0,"✔ All records valid – no exceptions","⚠ "&COUNTIFS(Salary_Calculation[Payment Status],"Review Required",Salary_Calculation[Salary Month],">="&Dash_Start,Salary_Calculation[Salary Month],"<"&Dash_End)&" record(s) require review – see the Exception Report below") -> ✔ All records valid – no exceptions
B17: PAYROLL COMPOSITION | تكوين الرواتب | H17: PAYMENT STATUS | حالات الدفع
B33: STATUS BREAKDOWN | توزيع الحالات | H33: TOP 10 BY FINAL SALARY | أعلى ١٠ رواتب
B34: Status | E34: Riders | F34: Share | H34: # | I34: Rider ID | J34: Rider Name | L34: Final Salary | M34: Orders | Q34: Top-10 row index
B35: Paid in Full | E35: =COUNTIFS(Salary_Calculation[Payment Status],$B35,Salary_Calculation[Salary Month],">="&Dash_Start,Salary_Calculation[Salary Month],"<"&Dash_End) -> 0 | F35: =IF($B$8=0,0,E35/$B$8) -> 0 | H35: =IF($R35="","",1) -> 1 | I35: =IF($R35="","",INDEX(Payslip_Lookup[Rider ID],$R35)) -> 4648308 | J35: =IF($R35="","",INDEX(Payslip_Lookup[Rider Name],$R35)) -> Rider 4648308 | L35: =IF($R35="","",INDEX(Payslip_Lookup[Final Salary],$R35)) -> 2721.55 | M35: =IF($R35="","",INDEX(Payslip_Lookup[Completed Orders],$R35)) -> 551 | R35: =IFERROR(MATCH(LARGE(Payslip_Data!$AM$2:$AM$501,1),Payslip_Data!$AM$2:$AM$501,0),"") -> 11
B36: Paid After Deductions | E36: =COUNTIFS(Salary_Calculation[Payment Status],$B36,Salary_Calculation[Salary Month],">="&Dash_Start,Salary_Calculation[Salary Month],"<"&Dash_End) -> 11 | F36: =IF($B$8=0,0,E36/$B$8) -> 0.73333333 | H36: =IF($R36="","",2) -> 2 | I36: =IF($R36="","",INDEX(Payslip_Lookup[Rider ID],$R36)) -> 4747290 | J36: =IF($R36="","",INDEX(Payslip_Lookup[Rider Name],$R36)) -> Rider 4747290 | L36: =IF($R36="","",INDEX(Payslip_Lookup[Final Salary],$R36)) -> 2240.64 | M36: =IF($R36="","",INDEX(Payslip_Lookup[Completed Orders],$R36)) -> 498 | R36: =IFERROR(MATCH(LARGE(Payslip_Data!$AM$2:$AM$501,2),Payslip_Data!$AM$2:$AM$501,0),"") -> 7
B37: No Salary – Amount Due from Rider | E37: =COUNTIFS(Salary_Calculation[Payment Status],$B37,Salary_Calculation[Salary Month],">="&Dash_Start,Salary_Calculation[Salary Month],"<"&Dash_End) -> 4 | F37: =IF($B$8=0,0,E37/$B$8) -> 0.26666667 | H37: =IF($R37="","",3) -> 3 | I37: =IF($R37="","",INDEX(Payslip_Lookup[Rider ID],$R37)) -> 4611383 | J37: =IF($R37="","",INDEX(Payslip_Lookup[Rider Name],$R37)) -> Rider 4611383 | L37: =IF($R37="","",INDEX(Payslip_Lookup[Final Salary],$R37)) -> 1848.27 | M37: =IF($R37="","",INDEX(Payslip_Lookup[Completed Orders],$R37)) -> 476 | R37: =IFERROR(MATCH(LARGE(Payslip_Data!$AM$2:$AM$501,3),Payslip_Data!$AM$2:$AM$501,0),"") -> 15
B38: No Orders | E38: =COUNTIFS(Salary_Calculation[Payment Status],$B38,Salary_Calculation[Salary Month],">="&Dash_Start,Salary_Calculation[Salary Month],"<"&Dash_End) -> 0 | F38: =IF($B$8=0,0,E38/$B$8) -> 0 | H38: =IF($R38="","",4) -> 4 | I38: =IF($R38="","",INDEX(Payslip_Lookup[Rider ID],$R38)) -> 4643856 | J38: =IF($R38="","",INDEX(Payslip_Lookup[Rider Name],$R38)) -> Rider 4643856 | L38: =IF($R38="","",INDEX(Payslip_Lookup[Final Salary],$R38)) -> 1675.29 | M38: =IF($R38="","",INDEX(Payslip_Lookup[Completed Orders],$R38)) -> 449 | R38: =IFERROR(MATCH(LARGE(Payslip_Data!$AM$2:$AM$501,4),Payslip_Data!$AM$2:$AM$501,0),"") -> 13
B39: Review Required | E39: =COUNTIFS(Salary_Calculation[Payment Status],$B39,Salary_Calculation[Salary Month],">="&Dash_Start,Salary_Calculation[Salary Month],"<"&Dash_End) -> 0 | F39: =IF($B$8=0,0,E39/$B$8) -> 0 | H39: =IF($R39="","",5) -> 5 | I39: =IF($R39="","",INDEX(Payslip_Lookup[Rider ID],$R39)) -> 4642935 | J39: =IF($R39="","",INDEX(Payslip_Lookup[Rider Name],$R39)) -> Rider 4642935 | L39: =IF($R39="","",INDEX(Payslip_Lookup[Final Salary],$R39)) -> 1602.49 | M39: =IF($R39="","",INDEX(Payslip_Lookup[Completed Orders],$R39)) -> 442 | R39: =IFERROR(MATCH(LARGE(Payslip_Data!$AM$2:$AM$501,5),Payslip_Data!$AM$2:$AM$501,0),"") -> 14
H40: =IF($R40="","",6) -> 6 | I40: =IF($R40="","",INDEX(Payslip_Lookup[Rider ID],$R40)) -> 4652654 | J40: =IF($R40="","",INDEX(Payslip_Lookup[Rider Name],$R40)) -> Rider 4652654 | L40: =IF($R40="","",INDEX(Payslip_Lookup[Final Salary],$R40)) -> 1454.79 | M40: =IF($R40="","",INDEX(Payslip_Lookup[Completed Orders],$R40)) -> 433 | R40: =IFERROR(MATCH(LARGE(Payslip_Data!$AM$2:$AM$501,6),Payslip_Data!$AM$2:$AM$501,0),"") -> 8
H41: =IF($R41="","",7) -> 7 | I41: =IF($R41="","",INDEX(Payslip_Lookup[Rider ID],$R41)) -> 4648709 | J41: =IF($R41="","",INDEX(Payslip_Lookup[Rider Name],$R41)) -> Rider 4648709 | L41: =IF($R41="","",INDEX(Payslip_Lookup[Final Salary],$R41)) -> 877.6 | M41: =IF($R41="","",INDEX(Payslip_Lookup[Completed Orders],$R41)) -> 391 | R41: =IFERROR(MATCH(LARGE(Payslip_Data!$AM$2:$AM$501,7),Payslip_Data!$AM$2:$AM$501,0),"") -> 10
H42: =IF($R42="","",8) -> 8 | I42: =IF($R42="","",INDEX(Payslip_Lookup[Rider ID],$R42)) -> 4644774 | J42: =IF($R42="","",INDEX(Payslip_Lookup[Rider Name],$R42)) -> Rider 4644774 | L42: =IF($R42="","",INDEX(Payslip_Lookup[Final Salary],$R42)) -> 617.8 | M42: =IF($R42="","",INDEX(Payslip_Lookup[Completed Orders],$R42)) -> 367 | R42: =IFERROR(MATCH(LARGE(Payslip_Data!$AM$2:$AM$501,8),Payslip_Data!$AM$2:$AM$501,0),"") -> 12
H43: =IF($R43="","",9) -> 9 | I43: =IF($R43="","",INDEX(Payslip_Lookup[Rider ID],$R43)) -> 4652587 | J43: =IF($R43="","",INDEX(Payslip_Lookup[Rider Name],$R43)) -> Rider 4652587 | L43: =IF($R43="","",INDEX(Payslip_Lookup[Final Salary],$R43)) -> 555.86 | M43: =IF($R43="","",INDEX(Payslip_Lookup[Completed Orders],$R43)) -> 382 | R43: =IFERROR(MATCH(LARGE(Payslip_Data!$AM$2:$AM$501,9),Payslip_Data!$AM$2:$AM$501,0),"") -> 9
H44: =IF($R44="","",10) -> 10 | I44: =IF($R44="","",INDEX(Payslip_Lookup[Rider ID],$R44)) -> 4844480 | J44: =IF($R44="","",INDEX(Payslip_Lookup[Rider Name],$R44)) -> Rider 4844480 | L44: =IF($R44="","",INDEX(Payslip_Lookup[Final Salary],$R44)) -> 363.5 | M44: =IF($R44="","",INDEX(Payslip_Lookup[Completed Orders],$R44)) -> 150 | R44: =IFERROR(MATCH(LARGE(Payslip_Data!$AM$2:$AM$501,10),Payslip_Data!$AM$2:$AM$501,0),"") -> 4
B47: EXCEPTION REPORT | تقرير الاستثناءات – invalid or incomplete records (all months)
B48: =COUNTIF(Payslip_Lookup[Payment Status],"Review Required")&" record(s) need review"&IF(COUNTIF(Payslip_Lookup[Payment Status],"Review Required")>25," (first 25 shown – filter Salary_Calculation on Payment Status for all)","") -> 0 record(s) need review
B49: # | C49: Rider ID | D49: Month | E49: Rider Name | G49: Reason | السبب
B50: =IF(1<=COUNTIF(Payslip_Lookup[Payment Status],"Review Required"),1,"") | C50: =IF($B50="","",INDEX(Payslip_Lookup[Rider ID],MATCH($B50,Payslip_Lookup[Exception Seq],0))) | D50: =IF($B50="","",INDEX(Payslip_Lookup[Salary Month],MATCH($B50,Payslip_Lookup[Exception Seq],0))) | E50: =IF($B50="","",INDEX(Payslip_Lookup[Rider Name],MATCH($B50,Payslip_Lookup[Exception Seq],0))) | G50: =IF($B50="","",INDEX(Payslip_Lookup[Exception Reason],MATCH($B50,Payslip_Lookup[Exception Seq],0)))
B51: =IF(2<=COUNTIF(Payslip_Lookup[Payment Status],"Review Required"),2,"") | C51: =IF($B51="","",INDEX(Payslip_Lookup[Rider ID],MATCH($B51,Payslip_Lookup[Exception Seq],0))) | D51: =IF($B51="","",INDEX(Payslip_Lookup[Salary Month],MATCH($B51,Payslip_Lookup[Exception Seq],0))) | E51: =IF($B51="","",INDEX(Payslip_Lookup[Rider Name],MATCH($B51,Payslip_Lookup[Exception Seq],0))) | G51: =IF($B51="","",INDEX(Payslip_Lookup[Exception Reason],MATCH($B51,Payslip_Lookup[Exception Seq],0)))
B52: =IF(3<=COUNTIF(Payslip_Lookup[Payment Status],"Review Required"),3,"") | C52: =IF($B52="","",INDEX(Payslip_Lookup[Rider ID],MATCH($B52,Payslip_Lookup[Exception Seq],0))) | D52: =IF($B52="","",INDEX(Payslip_Lookup[Salary Month],MATCH($B52,Payslip_Lookup[Exception Seq],0))) | E52: =IF($B52="","",INDEX(Payslip_Lookup[Rider Name],MATCH($B52,Payslip_Lookup[Exception Seq],0))) | G52: =IF($B52="","",INDEX(Payslip_Lookup[Exception Reason],MATCH($B52,Payslip_Lookup[Exception Seq],0)))
B53: =IF(4<=COUNTIF(Payslip_Lookup[Payment Status],"Review Required"),4,"") | C53: =IF($B53="","",INDEX(Payslip_Lookup[Rider ID],MATCH($B53,Payslip_Lookup[Exception Seq],0))) | D53: =IF($B53="","",INDEX(Payslip_Lookup[Salary Month],MATCH($B53,Payslip_Lookup[Exception Seq],0))) | E53: =IF($B53="","",INDEX(Payslip_Lookup[Rider Name],MATCH($B53,Payslip_Lookup[Exception Seq],0))) | G53: =IF($B53="","",INDEX(Payslip_Lookup[Exception Reason],MATCH($B53,Payslip_Lookup[Exception Seq],0)))
B54: =IF(5<=COUNTIF(Payslip_Lookup[Payment Status],"Review Required"),5,"") | C54: =IF($B54="","",INDEX(Payslip_Lookup[Rider ID],MATCH($B54,Payslip_Lookup[Exception Seq],0))) | D54: =IF($B54="","",INDEX(Payslip_Lookup[Salary Month],MATCH($B54,Payslip_Lookup[Exception Seq],0))) | E54: =IF($B54="","",INDEX(Payslip_Lookup[Rider Name],MATCH($B54,Payslip_Lookup[Exception Seq],0))) | G54: =IF($B54="","",INDEX(Payslip_Lookup[Exception Reason],MATCH($B54,Payslip_Lookup[Exception Seq],0)))
B55: =IF(6<=COUNTIF(Payslip_Lookup[Payment Status],"Review Required"),6,"") | C55: =IF($B55="","",INDEX(Payslip_Lookup[Rider ID],MATCH($B55,Payslip_Lookup[Exception Seq],0))) | D55: =IF($B55="","",INDEX(Payslip_Lookup[Salary Month],MATCH($B55,Payslip_Lookup[Exception Seq],0))) | E55: =IF($B55="","",INDEX(Payslip_Lookup[Rider Name],MATCH($B55,Payslip_Lookup[Exception Seq],0))) | G55: =IF($B55="","",INDEX(Payslip_Lookup[Exception Reason],MATCH($B55,Payslip_Lookup[Exception Seq],0)))
B56: =IF(7<=COUNTIF(Payslip_Lookup[Payment Status],"Review Required"),7,"") | C56: =IF($B56="","",INDEX(Payslip_Lookup[Rider ID],MATCH($B56,Payslip_Lookup[Exception Seq],0))) | D56: =IF($B56="","",INDEX(Payslip_Lookup[Salary Month],MATCH($B56,Payslip_Lookup[Exception Seq],0))) | E56: =IF($B56="","",INDEX(Payslip_Lookup[Rider Name],MATCH($B56,Payslip_Lookup[Exception Seq],0))) | G56: =IF($B56="","",INDEX(Payslip_Lookup[Exception Reason],MATCH($B56,Payslip_Lookup[Exception Seq],0)))
B57: =IF(8<=COUNTIF(Payslip_Lookup[Payment Status],"Review Required"),8,"") | C57: =IF($B57="","",INDEX(Payslip_Lookup[Rider ID],MATCH($B57,Payslip_Lookup[Exception Seq],0))) | D57: =IF($B57="","",INDEX(Payslip_Lookup[Salary Month],MATCH($B57,Payslip_Lookup[Exception Seq],0))) | E57: =IF($B57="","",INDEX(Payslip_Lookup[Rider Name],MATCH($B57,Payslip_Lookup[Exception Seq],0))) | G57: =IF($B57="","",INDEX(Payslip_Lookup[Exception Reason],MATCH($B57,Payslip_Lookup[Exception Seq],0)))
B58: =IF(9<=COUNTIF(Payslip_Lookup[Payment Status],"Review Required"),9,"") | C58: =IF($B58="","",INDEX(Payslip_Lookup[Rider ID],MATCH($B58,Payslip_Lookup[Exception Seq],0))) | D58: =IF($B58="","",INDEX(Payslip_Lookup[Salary Month],MATCH($B58,Payslip_Lookup[Exception Seq],0))) | E58: =IF($B58="","",INDEX(Payslip_Lookup[Rider Name],MATCH($B58,Payslip_Lookup[Exception Seq],0))) | G58: =IF($B58="","",INDEX(Payslip_Lookup[Exception Reason],MATCH($B58,Payslip_Lookup[Exception Seq],0)))
B59: =IF(10<=COUNTIF(Payslip_Lookup[Payment Status],"Review Required"),10,"") | C59: =IF($B59="","",INDEX(Payslip_Lookup[Rider ID],MATCH($B59,Payslip_Lookup[Exception Seq],0))) | D59: =IF($B59="","",INDEX(Payslip_Lookup[Salary Month],MATCH($B59,Payslip_Lookup[Exception Seq],0))) | E59: =IF($B59="","",INDEX(Payslip_Lookup[Rider Name],MATCH($B59,Payslip_Lookup[Exception Seq],0))) | G59: =IF($B59="","",INDEX(Payslip_Lookup[Exception Reason],MATCH($B59,Payslip_Lookup[Exception Seq],0)))
B60: =IF(11<=COUNTIF(Payslip_Lookup[Payment Status],"Review Required"),11,"") | C60: =IF($B60="","",INDEX(Payslip_Lookup[Rider ID],MATCH($B60,Payslip_Lookup[Exception Seq],0))) | D60: =IF($B60="","",INDEX(Payslip_Lookup[Salary Month],MATCH($B60,Payslip_Lookup[Exception Seq],0))) | E60: =IF($B60="","",INDEX(Payslip_Lookup[Rider Name],MATCH($B60,Payslip_Lookup[Exception Seq],0))) | G60: =IF($B60="","",INDEX(Payslip_Lookup[Exception Reason],MATCH($B60,Payslip_Lookup[Exception Seq],0)))
B61: =IF(12<=COUNTIF(Payslip_Lookup[Payment Status],"Review Required"),12,"") | C61: =IF($B61="","",INDEX(Payslip_Lookup[Rider ID],MATCH($B61,Payslip_Lookup[Exception Seq],0))) | D61: =IF($B61="","",INDEX(Payslip_Lookup[Salary Month],MATCH($B61,Payslip_Lookup[Exception Seq],0))) | E61: =IF($B61="","",INDEX(Payslip_Lookup[Rider Name],MATCH($B61,Payslip_Lookup[Exception Seq],0))) | G61: =IF($B61="","",INDEX(Payslip_Lookup[Exception Reason],MATCH($B61,Payslip_Lookup[Exception Seq],0)))
...

Sheet Payslip_Print
B1: SELECT PAYSLIP | اختيار القسيمة
B2: Month / الشهر ▸ | C2: =Salary_Month -> 46235 | E2: Rider ID / المندوب ▸ | F2: =Payslip_Data!AL2 -> 4849914 | H2: Print: File ▸ Print ▸ PDF
B3: Record # (auto) | C3: =IFERROR(MATCH($F$2&"|"&$C$2,Payslip_Lookup[Key],0),"") -> 1 | E3: =IF($C$3="","⚠ No record for this month + rider. Choose the month first, then the rider.","✔ Record found – payslip ready to print.") -> ✔ Record found – payslip ready to print.
E6: PAYSLIP | قسيمة راتب
E7: =IF($C$3="","",TEXT(INDEX(Payslip_Lookup[Salary Month],$C$3),"dd mmm yyyy")&" – "&TEXT(EOMONTH(INDEX(Payslip_Lookup[Salary Month],$C$3),0),"dd mmm yyyy")) -> 01 Aug 2026 – 31 Aug 2026
E8: =IF($C$3="","","Payslip No. PS-"&TEXT(INDEX(Payslip_Lookup[Salary Month],$C$3),"yyyymm")&"-"&INDEX(Payslip_Lookup[Rider ID],$C$3)) -> Payslip No. PS-202608-4849914
E9: ="Issued by "&Company_Name&" · Payroll Department" -> Issued by Elite Development · Payroll Department
B11: RIDER | المندوب | F11: PAYMENT STATUS | حالة الدفع
B12: =IF($C$3="","",INDEX(Payslip_Lookup[Rider Name],$C$3)) -> Rider 4849914 | F12: =IF($C$3="","",INDEX(Payslip_Lookup[Payment Status],$C$3)) -> No Salary – Amount Due from Rider
B13: =IF($C$3="","","Rider ID "&INDEX(Payslip_Lookup[Rider ID],$C$3)) -> Rider ID 4849914
B14: =IF($C$3="","","Salary month: "&TEXT(INDEX(Payslip_Lookup[Salary Month],$C$3),"mmmm yyyy")) -> Salary month: August 2026 | F14: =IF($C$3="","","Base rate SAR "&TEXT(INDEX(Payslip_Lookup[Base Order Rate],$C$3),"0.00")&" / order · "&Rate_Method) -> Base rate SAR 4.44 / order · Exact rate
B16: WORKING DAYS | أيام العمل | D16: TARGET ORDERS | الهدف | F16: COMPLETED | المكتملة | H16: ACHIEVEMENT | الإنجاز
B17: =IF($C$3="","",INDEX(Payslip_Lookup[Working Days],$C$3)) -> 8 | D17: =IF($C$3="","",INDEX(Payslip_Lookup[Rider Target Orders],$C$3)) -> 120 | F17: =IF($C$3="","",INDEX(Payslip_Lookup[Completed Orders],$C$3)) -> 72 | H17: =IF(OR($C$3="",N(INDEX(Payslip_Lookup[Rider Target Orders],$C$3))=0),"",INDEX(Payslip_Lookup[Completed Orders],$C$3)/INDEX(Payslip_Lookup[Rider Target Orders],$C$3)) -> 0.6
B18: =IF($C$3="","","of "&INDEX(Payslip_Lookup[Calendar Days],$C$3)&" calendar days") -> of 31 calendar days | D18: =IF($C$3="","","monthly target "&TEXT(INDEX(Payslip_Lookup[Monthly Target Orders],$C$3),"0.##")) -> monthly target 465 | F18: =IF($C$3="","",IF(INDEX(Payslip_Lookup[Extra Orders],$C$3)>0,"▲ "&TEXT(INDEX(Payslip_Lookup[Extra Orders],$C$3),"0.##")&" extra orders",IF(INDEX(Payslip_Lookup[Missing Orders],$C$3)>0,"▼ "&TEXT(INDEX(Payslip_Lookup[Missing Orders],$C$3),"0.##")&" missing orders","target met"))) -> ▼ 48 missing orders | H18: =IF($C$3="","","completed ÷ target") -> completed ÷ target
B20: EARNINGS | المستحقات | F20: DEDUCTIONS | الخصومات
B21: Basic Payment (contract) | الدفعة الأساسية | E21: =IF($C$3="","",INDEX(Payslip_Lookup[Basic Payment],$C$3)) -> 2000 | F21: Missing Orders | الطلبات الناقصة | I21: =IF($C$3="","",INDEX(Payslip_Lookup[Missing Orders],$C$3)) -> 48
B22: Orders counted at base rate | الطلبات بالسعر الأساسي | E22: =IF($C$3="","",INDEX(Payslip_Lookup[Orders Counted at Base Rate],$C$3)) -> 72 | F22: Missing-Order Deduction | خصم الطلبات الناقصة | I22: =IF($C$3="","",INDEX(Payslip_Lookup[Missing-Order Deduction],$C$3)) -> 336
B23: Earned Salary | الراتب المكتسب | E23: =IF($C$3="","",INDEX(Payslip_Lookup[Earned Salary],$C$3)) -> 320 | F23: missed_days_penalty | غرامة الأيام الفائتة | I23: =IF($C$3="","",INDEX(Payslip_Lookup[missed_days_penalty],$C$3)) -> 0
B24: Extra Orders | الطلبات الإضافية | E24: =IF($C$3="","",INDEX(Payslip_Lookup[Extra Orders],$C$3)) -> 0 | F24: Rider Balance | محفظة المندوب | I24: =IF($C$3="","",INDEX(Payslip_Lookup[Rider Balance],$C$3)) -> 268.09
B25: Extra-Order Bonus | مكافأة الطلبات الإضافية | E25: =IF($C$3="","",INDEX(Payslip_Lookup[Extra-Order Bonus],$C$3)) -> 0 | F25: stacking_deduction | خصم الطلبات المتعددة | I25: =IF($C$3="","",INDEX(Payslip_Lookup[stacking_deduction],$C$3)) -> 32
B26: Basic Salary at Target | الراتب الأساسي للهدف | E26: =IF($C$3="","",INDEX(Payslip_Lookup[Basic Salary for Target],$C$3)) -> 533.33333 | F26: Other Deductions | خصومات أخرى | I26: =IF($C$3="","",INDEX(Payslip_Lookup[Other Deductions],$C$3)) -> 0
B27: GROSS SALARY | إجمالي الراتب قبل الخصم | E27: =IF($C$3="","",INDEX(Payslip_Lookup[Gross Salary Before Deductions],$C$3)) -> 0 | F27: TOTAL DEDUCTIONS | إجمالي الخصومات | I27: =IF($C$3="","",INDEX(Payslip_Lookup[Total Deductions],$C$3)) -> 300.09
B29: FINAL SALARY (PAYABLE) | صافي الراتب المستحق | F29: NEGATIVE BALANCE / AMOUNT DUE FROM RIDER | المبلغ المستحق على المندوب
B30: =IF($C$3="","",INDEX(Payslip_Lookup[Final Salary],$C$3)) -> 0 | F30: =IF($C$3="","",INDEX(Payslip_Lookup[Negative Balance / Amount Due from Rider],$C$3)) -> 16
B32: =IF($C$3="","","Salary before other deductions: SAR "&TEXT(INDEX(Payslip_Lookup[Salary Before Other Deductions],$C$3),"#,##0.00;-#,##0.00")) -> Salary before other deductions: SAR -16.00 | F32: =IF($C$3="","","Total amount due from rider (incl. deductions beyond salary): SAR "&TEXT(INDEX(Payslip_Lookup[Total Amount Due from Rider],$C$3),"#,##0.00")) -> Total amount due from rider (incl. deductions beyond salary): SAR 316.09
B34: HOW THIS WAS CALCULATED | طريقة الحساب
B35: =IF($C$3="","","① Rider target = monthly target "&TEXT(INDEX(Payslip_Lookup[Monthly Target Orders],$C$3),"0.##")&" ÷ "&INDEX(Payslip_Lookup[Calendar Days],$C$3)&" days × "&INDEX(Payslip_Lookup[Working Days],$C$3)&" working days = "&TEXT(INDEX(Payslip_Lookup[Rider Target Orders],$C$3),"0.00")&" orders") -> ① Rider target = monthly target 465 ÷ 31 days × 8 working days = 120.00 orders
B36: =IF($C$3="","","② Earned salary = "&TEXT(INDEX(Payslip_Lookup[Orders Counted at Base Rate],$C$3),"0.00")&" orders × SAR "&TEXT(INDEX(Payslip_Lookup[Base Order Rate],$C$3),"0.00")&" = SAR "&TEXT(INDEX(Payslip_Lookup[Earned Salary],$C$3),"#,##0.00")) -> ② Earned salary = 72.00 orders × SAR 4.44 = SAR 320.00
B37: =IF($C$3="","","③ "&IF(INDEX(Payslip_Lookup[Missing Orders],$C$3)>0,"Shortfall: "&TEXT(INDEX(Payslip_Lookup[Missing Orders],$C$3),"0.##")&" missing orders × SAR "&Missing_Rate&" = SAR "&TEXT(INDEX(Payslip_Lookup[Missing-Order Deduction],$C$3),"#,##0.00")&" deducted",IF(INDEX(Payslip_Lookup[Extra Orders],$C$3)>0,"Bonus: "&TEXT(INDEX(Payslip_Lookup[Extra Orders],$C$3),"0.##")&" extra orders × SAR "&Extra_Rate&" = SAR "&TEXT(INDEX(Payslip_Lookup[Extra-Order Bonus],$C$3),"#,##0.00"),"Target met exactly – no shortfall or bonus"))) -> ③ Shortfall: 48 missing orders × SAR 7 = SAR 336.00 deducted
B39: NOTES | ملاحظات
B40: =IF($C$3="","",INDEX(Payslip_Lookup[Notes],$C$3)&IF(INDEX(Payslip_Lookup[Exception Reason],$C$3)<>""," ⚠ REVIEW REQUIRED: "&INDEX(Payslip_Lookup[Exception Reason],$C$3),""))
B44: Rider Signature | توقيع المندوب | E44: Payroll Officer | مسؤول الرواتب | H44: Approved by | اعتماد الإدارة
B45: Date / التاريخ: ____ / ____ / ________ | E45: Date / التاريخ: ____ / ____ / ________ | H45: Date / التاريخ: ____ / ____ / ________
B48: =Company_Name&" · System-generated payslip · Amounts in Saudi Riyals (SAR) · المبالغ بالريال السعودي" -> Elite Development · System-generated payslip · Amounts in Saudi Riyals (SAR) · المبالغ بالريال السعودي

Sheet Monthly_Import
B1: Monthly Import – new month in 5 minutes / الاستيراد الشهري
B3: 1. Save last month's file as a copy (e.g. Salary_2026-08.xlsx) – keep it as your archive, then reuse this file. | I3: Helper area – formulas only, do not edit
B4: 2. Settings → B13: type the new Salary Month (calendar days are calculated automatically).
B5: 3. Paste_FTR: select row 2 downward → Delete, then paste the new 'FTR Cost' export from cell A1 (header row included). | I5: # | J5: Rider ID | K5: Row in RLVL | L5: In Rider_Master? | M5: Orders FTR | N5: Orders RLVL | O5: Duplicate? | P5: Issue | Q5: Issue #
B6: 4. Paste_RLVL: same – delete old rows, paste the new RLVL export from A1. | I6: 1 | J6: =IFERROR(IF(INDEX(Rider_Input[Rider ID],I6)="","",INDEX(Rider_Input[Rider ID],I6)),"") -> 4849914 | K6: =IF(J6="","",IFERROR(MATCH(J6,INDEX(RLVL_Data,0,c_RLVL_ID),0),"")) -> 15 | L6: =IF(J6="","",IF(ISNUMBER(MATCH(J6,Rider_Master[Rider ID],0)),1,0)) -> 1 | M6: =IF(J6="","",INDEX(Rider_Input[Completed Orders],I6)) -> 72 | N6: =IF(OR(J6="",K6=""),"",IFERROR(INDEX(RLVL_Data,K6,c_RLVL_Orders),"")) -> 72 | O6: =IF(J6="","",IF(COUNTIF($J$6:$J$505,J6)>1,1,0)) -> 0 | P6: =IF(J6="","",IF(K6="","Not found in Paste_RLVL – deductions set to 0; ","")&IF(L6=0,"New rider (not in Rider_Master) – OK, shown as Rider <ID>; ","")&IF(AND(N6<>"",N6<>M6),"Orders differ: FTR "&M6&" vs RLVL "&N6&"; ","")&IF(O6=1,"Duplicate Rider ID; ","")) | Q6: =IF(P6="","",COUNTIF(P$6:P6,"?*"))
B7: 5. Adjustments (optional): clear last month's rows, add this month's Other Deductions (car, TGA, advances…). | I7: 2 | J7: =IFERROR(IF(INDEX(Rider_Input[Rider ID],I7)="","",INDEX(Rider_Input[Rider ID],I7)),"") -> 4849909 | K7: =IF(J7="","",IFERROR(MATCH(J7,INDEX(RLVL_Data,0,c_RLVL_ID),0),"")) -> 14 | L7: =IF(J7="","",IF(ISNUMBER(MATCH(J7,Rider_Master[Rider ID],0)),1,0)) -> 1 | M7: =IF(J7="","",INDEX(Rider_Input[Completed Orders],I7)) -> 101 | N7: =IF(OR(J7="",K7=""),"",IFERROR(INDEX(RLVL_Data,K7,c_RLVL_Orders),"")) -> 101 | O7: =IF(J7="","",IF(COUNTIF($J$6:$J$505,J7)>1,1,0)) -> 0 | P7: =IF(J7="","",IF(K7="","Not found in Paste_RLVL – deductions set to 0; ","")&IF(L7=0,"New rider (not in Rider_Master) – OK, shown as Rider <ID>; ","")&IF(AND(N7<>"",N7<>M7),"Orders differ: FTR "&M7&" vs RLVL "&N7&"; ","")&IF(O7=1,"Duplicate Rider ID; ","")) | Q7: =IF(P7="","",COUNTIF(P$6:P7,"?*"))
B8: 6. Come back here: banner must say READY. Fix anything under 'Items to review'. New riders appear automatically – no setup needed. | I8: 3 | J8: =IFERROR(IF(INDEX(Rider_Input[Rider ID],I8)="","",INDEX(Rider_Input[Rider ID],I8)),"") -> 4849222 | K8: =IF(J8="","",IFERROR(MATCH(J8,INDEX(RLVL_Data,0,c_RLVL_ID),0),"")) -> 13 | L8: =IF(J8="","",IF(ISNUMBER(MATCH(J8,Rider_Master[Rider ID],0)),1,0)) -> 1 | M8: =IF(J8="","",INDEX(Rider_Input[Completed Orders],I8)) -> 105 | N8: =IF(OR(J8="",K8=""),"",IFERROR(INDEX(RLVL_Data,K8,c_RLVL_Orders),"")) -> 105 | O8: =IF(J8="","",IF(COUNTIF($J$6:$J$505,J8)>1,1,0)) -> 0 | P8: =IF(J8="","",IF(K8="","Not found in Paste_RLVL – deductions set to 0; ","")&IF(L8=0,"New rider (not in Rider_Master) – OK, shown as Rider <ID>; ","")&IF(AND(N8<>"",N8<>M8),"Orders differ: FTR "&M8&" vs RLVL "&N8&"; ","")&IF(O8=1,"Duplicate Rider ID; ","")) | Q8: =IF(P8="","",COUNTIF(P$6:P8,"?*"))
B9: 7. Summary_Dashboard for totals, Payslip_Print for payslips (print or Save as PDF). | I9: 4 | J9: =IFERROR(IF(INDEX(Rider_Input[Rider ID],I9)="","",INDEX(Rider_Input[Rider ID],I9)),"") -> 4844480 | K9: =IF(J9="","",IFERROR(MATCH(J9,INDEX(RLVL_Data,0,c_RLVL_ID),0),"")) -> 12 | L9: =IF(J9="","",IF(ISNUMBER(MATCH(J9,Rider_Master[Rider ID],0)),1,0)) -> 1 | M9: =IF(J9="","",INDEX(Rider_Input[Completed Orders],I9)) -> 150 | N9: =IF(OR(J9="",K9=""),"",IFERROR(INDEX(RLVL_Data,K9,c_RLVL_Orders),"")) -> 150 | O9: =IF(J9="","",IF(COUNTIF($J$6:$J$505,J9)>1,1,0)) -> 0 | P9: =IF(J9="","",IF(K9="","Not found in Paste_RLVL – deductions set to 0; ","")&IF(L9=0,"New rider (not in Rider_Master) – OK, shown as Rider <ID>; ","")&IF(AND(N9<>"",N9<>M9),"Orders differ: FTR "&M9&" vs RLVL "&N9&"; ","")&IF(O9=1,"Duplicate Rider ID; ","")) | Q9: =IF(P9="","",COUNTIF(P$6:P9,"?*"))
I10: 5 | J10: =IFERROR(IF(INDEX(Rider_Input[Rider ID],I10)="","",INDEX(Rider_Input[Rider ID],I10)),"") -> 4838478 | K10: =IF(J10="","",IFERROR(MATCH(J10,INDEX(RLVL_Data,0,c_RLVL_ID),0),"")) -> 11 | L10: =IF(J10="","",IF(ISNUMBER(MATCH(J10,Rider_Master[Rider ID],0)),1,0)) -> 1 | M10: =IF(J10="","",INDEX(Rider_Input[Completed Orders],I10)) -> 171 | N10: =IF(OR(J10="",K10=""),"",IFERROR(INDEX(RLVL_Data,K10,c_RLVL_Orders),"")) -> 171 | O10: =IF(J10="","",IF(COUNTIF($J$6:$J$505,J10)>1,1,0)) -> 0 | P10: =IF(J10="","",IF(K10="","Not found in Paste_RLVL – deductions set to 0; ","")&IF(L10=0,"New rider (not in Rider_Master) – OK, shown as Rider <ID>; ","")&IF(AND(N10<>"",N10<>M10),"Orders differ: FTR "&M10&" vs RLVL "&N10&"; ","")&IF(O10=1,"Duplicate Rider ID; ","")) | Q10: =IF(P10="","",COUNTIF(P$6:P10,"?*"))
B11: =IF(COUNTIF(D14:D23,"CHECK")=0,"✔ READY – all checks passed ("&C15&" riders loaded for "&TEXT(Salary_Month,"mmmm yyyy")&")","⚠ CHECK – "&COUNTIF(D14:D23,"CHECK")&" item(s) marked CHECK below; review before paying") -> ✔ READY – all checks passed (15 riders loaded for August 2026) | I11: 6 | J11: =IFERROR(IF(INDEX(Rider_Input[Rider ID],I11)="","",INDEX(Rider_Input[Rider ID],I11)),"") -> 4838471 | K11: =IF(J11="","",IFERROR(MATCH(J11,INDEX(RLVL_Data,0,c_RLVL_ID),0),"")) -> 10 | L11: =IF(J11="","",IF(ISNUMBER(MATCH(J11,Rider_Master[Rider ID],0)),1,0)) -> 1 | M11: =IF(J11="","",INDEX(Rider_Input[Completed Orders],I11)) -> 146 | N11: =IF(OR(J11="",K11=""),"",IFERROR(INDEX(RLVL_Data,K11,c_RLVL_Orders),"")) -> 146 | O11: =IF(J11="","",IF(COUNTIF($J$6:$J$505,J11)>1,1,0)) -> 0 | P11: =IF(J11="","",IF(K11="","Not found in Paste_RLVL – deductions set to 0; ","")&IF(L11=0,"New rider (not in Rider_Master) – OK, shown as Rider <ID>; ","")&IF(AND(N11<>"",N11<>M11),"Orders differ: FTR "&M11&" vs RLVL "&N11&"; ","")&IF(O11=1,"Duplicate Rider ID; ","")) | Q11: =IF(P11="","",COUNTIF(P$6:P11,"?*"))
I12: 7 | J12: =IFERROR(IF(INDEX(Rider_Input[Rider ID],I12)="","",INDEX(Rider_Input[Rider ID],I12)),"") -> 4747290 | K12: =IF(J12="","",IFERROR(MATCH(J12,INDEX(RLVL_Data,0,c_RLVL_ID),0),"")) -> 9 | L12: =IF(J12="","",IF(ISNUMBER(MATCH(J12,Rider_Master[Rider ID],0)),1,0)) -> 1 | M12: =IF(J12="","",INDEX(Rider_Input[Completed Orders],I12)) -> 498 | N12: =IF(OR(J12="",K12=""),"",IFERROR(INDEX(RLVL_Data,K12,c_RLVL_Orders),"")) -> 498 | O12: =IF(J12="","",IF(COUNTIF($J$6:$J$505,J12)>1,1,0)) -> 0 | P12: =IF(J12="","",IF(K12="","Not found in Paste_RLVL – deductions set to 0; ","")&IF(L12=0,"New rider (not in Rider_Master) – OK, shown as Rider <ID>; ","")&IF(AND(N12<>"",N12<>M12),"Orders differ: FTR "&M12&" vs RLVL "&N12&"; ","")&IF(O12=1,"Duplicate Rider ID; ","")) | Q12: =IF(P12="","",COUNTIF(P$6:P12,"?*"))
B13: Import Health / فحص الاستيراد | I13: 8 | J13: =IFERROR(IF(INDEX(Rider_Input[Rider ID],I13)="","",INDEX(Rider_Input[Rider ID],I13)),"") -> 4652654 | K13: =IF(J13="","",IFERROR(MATCH(J13,INDEX(RLVL_Data,0,c_RLVL_ID),0),"")) -> 8 | L13: =IF(J13="","",IF(ISNUMBER(MATCH(J13,Rider_Master[Rider ID],0)),1,0)) -> 1 | M13: =IF(J13="","",INDEX(Rider_Input[Completed Orders],I13)) -> 433 | N13: =IF(OR(J13="",K13=""),"",IFERROR(INDEX(RLVL_Data,K13,c_RLVL_Orders),"")) -> 433 | O13: =IF(J13="","",IF(COUNTIF($J$6:$J$505,J13)>1,1,0)) -> 0 | P13: =IF(J13="","",IF(K13="","Not found in Paste_RLVL – deductions set to 0; ","")&IF(L13=0,"New rider (not in Rider_Master) – OK, shown as Rider <ID>; ","")&IF(AND(N13<>"",N13<>M13),"Orders differ: FTR "&M13&" vs RLVL "&N13&"; ","")&IF(O13=1,"Duplicate Rider ID; ","")) | Q13: =IF(P13="","",COUNTIF(P$6:P13,"?*"))
B14: Salary Month set | C14: =IF(ISNUMBER(Salary_Month),Salary_Month,"MISSING") -> 46235 | D14: =IF(ISNUMBER(C14),"OK","CHECK") -> OK | I14: 9 | J14: =IFERROR(IF(INDEX(Rider_Input[Rider ID],I14)="","",INDEX(Rider_Input[Rider ID],I14)),"") -> 4652587 | K14: =IF(J14="","",IFERROR(MATCH(J14,INDEX(RLVL_Data,0,c_RLVL_ID),0),"")) -> 7 | L14: =IF(J14="","",IF(ISNUMBER(MATCH(J14,Rider_Master[Rider ID],0)),1,0)) -> 1 | M14: =IF(J14="","",INDEX(Rider_Input[Completed Orders],I14)) -> 382 | N14: =IF(OR(J14="",K14=""),"",IFERROR(INDEX(RLVL_Data,K14,c_RLVL_Orders),"")) -> 382 | O14: =IF(J14="","",IF(COUNTIF($J$6:$J$505,J14)>1,1,0)) -> 0 | P14: =IF(J14="","",IF(K14="","Not found in Paste_RLVL – deductions set to 0; ","")&IF(L14=0,"New rider (not in Rider_Master) – OK, shown as Rider <ID>; ","")&IF(AND(N14<>"",N14<>M14),"Orders differ: FTR "&M14&" vs RLVL "&N14&"; ","")&IF(O14=1,"Duplicate Rider ID; ","")) | Q14: =IF(P14="","",COUNTIF(P$6:P14,"?*"))
B15: Riders found in Paste_FTR | C15: =IFERROR(COUNT(INDEX(FTR_Data,0,c_FTR_ID)),0) -> 15 | D15: =IF(C15>0,"OK","CHECK") -> OK | I15: 10 | J15: =IFERROR(IF(INDEX(Rider_Input[Rider ID],I15)="","",INDEX(Rider_Input[Rider ID],I15)),"") -> 4648709 | K15: =IF(J15="","",IFERROR(MATCH(J15,INDEX(RLVL_Data,0,c_RLVL_ID),0),"")) -> 6 | L15: =IF(J15="","",IF(ISNUMBER(MATCH(J15,Rider_Master[Rider ID],0)),1,0)) -> 1 | M15: =IF(J15="","",INDEX(Rider_Input[Completed Orders],I15)) -> 391 | N15: =IF(OR(J15="",K15=""),"",IFERROR(INDEX(RLVL_Data,K15,c_RLVL_Orders),"")) -> 391 | O15: =IF(J15="","",IF(COUNTIF($J$6:$J$505,J15)>1,1,0)) -> 0 | P15: =IF(J15="","",IF(K15="","Not found in Paste_RLVL – deductions set to 0; ","")&IF(L15=0,"New rider (not in Rider_Master) – OK, shown as Rider <ID>; ","")&IF(AND(N15<>"",N15<>M15),"Orders differ: FTR "&M15&" vs RLVL "&N15&"; ","")&IF(O15=1,"Duplicate Rider ID; ","")) | Q15: =IF(P15="","",COUNTIF(P$6:P15,"?*"))
B16: Riders found in Paste_RLVL | C16: =IFERROR(COUNT(INDEX(RLVL_Data,0,c_RLVL_ID)),0) -> 15 | D16: =IF(C16>0,"OK","CHECK") -> OK | I16: 11 | J16: =IFERROR(IF(INDEX(Rider_Input[Rider ID],I16)="","",INDEX(Rider_Input[Rider ID],I16)),"") -> 4648308 | K16: =IF(J16="","",IFERROR(MATCH(J16,INDEX(RLVL_Data,0,c_RLVL_ID),0),"")) -> 5 | L16: =IF(J16="","",IF(ISNUMBER(MATCH(J16,Rider_Master[Rider ID],0)),1,0)) -> 1 | M16: =IF(J16="","",INDEX(Rider_Input[Completed Orders],I16)) -> 551 | N16: =IF(OR(J16="",K16=""),"",IFERROR(INDEX(RLVL_Data,K16,c_RLVL_Orders),"")) -> 551 | O16: =IF(J16="","",IF(COUNTIF($J$6:$J$505,J16)>1,1,0)) -> 0 | P16: =IF(J16="","",IF(K16="","Not found in Paste_RLVL – deductions set to 0; ","")&IF(L16=0,"New rider (not in Rider_Master) – OK, shown as Rider <ID>; ","")&IF(AND(N16<>"",N16<>M16),"Orders differ: FTR "&M16&" vs RLVL "&N16&"; ","")&IF(O16=1,"Duplicate Rider ID; ","")) | Q16: =IF(P16="","",COUNTIF(P$6:P16,"?*"))
B17: Riders loaded into salary engine (capacity 500) | C17: =COUNTIF(Rider_Input[Rider ID],">0") -> 15 | D17: =IF(AND(C17=C15,C15<=500),"OK","CHECK") -> OK | I17: 12 | J17: =IFERROR(IF(INDEX(Rider_Input[Rider ID],I17)="","",INDEX(Rider_Input[Rider ID],I17)),"") -> 4644774 | K17: =IF(J17="","",IFERROR(MATCH(J17,INDEX(RLVL_Data,0,c_RLVL_ID),0),"")) -> 4 | L17: =IF(J17="","",IF(ISNUMBER(MATCH(J17,Rider_Master[Rider ID],0)),1,0)) -> 1 | M17: =IF(J17="","",INDEX(Rider_Input[Completed Orders],I17)) -> 367 | N17: =IF(OR(J17="",K17=""),"",IFERROR(INDEX(RLVL_Data,K17,c_RLVL_Orders),"")) -> 367 | O17: =IF(J17="","",IF(COUNTIF($J$6:$J$505,J17)>1,1,0)) -> 0 | P17: =IF(J17="","",IF(K17="","Not found in Paste_RLVL – deductions set to 0; ","")&IF(L17=0,"New rider (not in Rider_Master) – OK, shown as Rider <ID>; ","")&IF(AND(N17<>"",N17<>M17),"Orders differ: FTR "&M17&" vs RLVL "&N17&"; ","")&IF(O17=1,"Duplicate Rider ID; ","")) | Q17: =IF(P17="","",COUNTIF(P$6:P17,"?*"))
B18: FTR riders missing from RLVL | C18: =SUMPRODUCT(($J$6:$J$505<>"")*($K$6:$K$505="")) -> 0 | D18: =IF(C18=0,"OK","CHECK") -> OK | I18: 13 | J18: =IFERROR(IF(INDEX(Rider_Input[Rider ID],I18)="","",INDEX(Rider_Input[Rider ID],I18)),"") -> 4643856 | K18: =IF(J18="","",IFERROR(MATCH(J18,INDEX(RLVL_Data,0,c_RLVL_ID),0),"")) -> 3 | L18: =IF(J18="","",IF(ISNUMBER(MATCH(J18,Rider_Master[Rider ID],0)),1,0)) -> 1 | M18: =IF(J18="","",INDEX(Rider_Input[Completed Orders],I18)) -> 449 | N18: =IF(OR(J18="",K18=""),"",IFERROR(INDEX(RLVL_Data,K18,c_RLVL_Orders),"")) -> 449 | O18: =IF(J18="","",IF(COUNTIF($J$6:$J$505,J18)>1,1,0)) -> 0 | P18: =IF(J18="","",IF(K18="","Not found in Paste_RLVL – deductions set to 0; ","")&IF(L18=0,"New rider (not in Rider_Master) – OK, shown as Rider <ID>; ","")&IF(AND(N18<>"",N18<>M18),"Orders differ: FTR "&M18&" vs RLVL "&N18&"; ","")&IF(O18=1,"Duplicate Rider ID; ","")) | Q18: =IF(P18="","",COUNTIF(P$6:P18,"?*"))
B19: RLVL riders missing from FTR | C19: =IFERROR(SUMPRODUCT((INDEX(RLVL_Data,0,c_RLVL_ID)<>"")*(COUNTIF(INDEX(FTR_Data,0,c_FTR_ID),INDEX(RLVL_Data,0,c_RLVL_ID))=0)),0) -> 0 | D19: =IF(C19=0,"OK","CHECK") -> OK | I19: 14 | J19: =IFERROR(IF(INDEX(Rider_Input[Rider ID],I19)="","",INDEX(Rider_Input[Rider ID],I19)),"") -> 4642935 | K19: =IF(J19="","",IFERROR(MATCH(J19,INDEX(RLVL_Data,0,c_RLVL_ID),0),"")) -> 2 | L19: =IF(J19="","",IF(ISNUMBER(MATCH(J19,Rider_Master[Rider ID],0)),1,0)) -> 1 | M19: =IF(J19="","",INDEX(Rider_Input[Completed Orders],I19)) -> 442 | N19: =IF(OR(J19="",K19=""),"",IFERROR(INDEX(RLVL_Data,K19,c_RLVL_Orders),"")) -> 442 | O19: =IF(J19="","",IF(COUNTIF($J$6:$J$505,J19)>1,1,0)) -> 0 | P19: =IF(J19="","",IF(K19="","Not found in Paste_RLVL – deductions set to 0; ","")&IF(L19=0,"New rider (not in Rider_Master) – OK, shown as Rider <ID>; ","")&IF(AND(N19<>"",N19<>M19),"Orders differ: FTR "&M19&" vs RLVL "&N19&"; ","")&IF(O19=1,"Duplicate Rider ID; ","")) | Q19: =IF(P19="","",COUNTIF(P$6:P19,"?*"))
B20: Orders differ between FTR and RLVL | C20: =SUMPRODUCT(($N$6:$N$505<>"")*($N$6:$N$505<>$M$6:$M$505)) -> 0 | D20: =IF(C20=0,"OK","CHECK") -> OK | I20: 15 | J20: =IFERROR(IF(INDEX(Rider_Input[Rider ID],I20)="","",INDEX(Rider_Input[Rider ID],I20)),"") -> 4611383 | K20: =IF(J20="","",IFERROR(MATCH(J20,INDEX(RLVL_Data,0,c_RLVL_ID),0),"")) -> 1 | L20: =IF(J20="","",IF(ISNUMBER(MATCH(J20,Rider_Master[Rider ID],0)),1,0)) -> 1 | M20: =IF(J20="","",INDEX(Rider_Input[Completed Orders],I20)) -> 476 | N20: =IF(OR(J20="",K20=""),"",IFERROR(INDEX(RLVL_Data,K20,c_RLVL_Orders),"")) -> 476 | O20: =IF(J20="","",IF(COUNTIF($J$6:$J$505,J20)>1,1,0)) -> 0 | P20: =IF(J20="","",IF(K20="","Not found in Paste_RLVL – deductions set to 0; ","")&IF(L20=0,"New rider (not in Rider_Master) – OK, shown as Rider <ID>; ","")&IF(AND(N20<>"",N20<>M20),"Orders differ: FTR "&M20&" vs RLVL "&N20&"; ","")&IF(O20=1,"Duplicate Rider ID; ","")) | Q20: =IF(P20="","",COUNTIF(P$6:P20,"?*"))
B21: Duplicate Rider IDs | C21: =SUM($O$6:$O$505) -> 0 | D21: =IF(C21=0,"OK","CHECK") -> OK | I21: 16 | J21: =IFERROR(IF(INDEX(Rider_Input[Rider ID],I21)="","",INDEX(Rider_Input[Rider ID],I21)),"") | K21: =IF(J21="","",IFERROR(MATCH(J21,INDEX(RLVL_Data,0,c_RLVL_ID),0),"")) | L21: =IF(J21="","",IF(ISNUMBER(MATCH(J21,Rider_Master[Rider ID],0)),1,0)) | M21: =IF(J21="","",INDEX(Rider_Input[Completed Orders],I21)) | N21: =IF(OR(J21="",K21=""),"",IFERROR(INDEX(RLVL_Data,K21,c_RLVL_Orders),"")) | O21: =IF(J21="","",IF(COUNTIF($J$6:$J$505,J21)>1,1,0)) | P21: =IF(J21="","",IF(K21="","Not found in Paste_RLVL – deductions set to 0; ","")&IF(L21=0,"New rider (not in Rider_Master) – OK, shown as Rider <ID>; ","")&IF(AND(N21<>"",N21<>M21),"Orders differ: FTR "&M21&" vs RLVL "&N21&"; ","")&IF(O21=1,"Duplicate Rider ID; ","")) | Q21: =IF(P21="","",COUNTIF(P$6:P21,"?*"))
B22: Column mapping: columns not found | C22: =COUNTIF(F28:F35,"MISSING") -> 0 | D22: =IF(C22=0,"OK","CHECK") -> OK | I22: 17 | J22: =IFERROR(IF(INDEX(Rider_Input[Rider ID],I22)="","",INDEX(Rider_Input[Rider ID],I22)),"") | K22: =IF(J22="","",IFERROR(MATCH(J22,INDEX(RLVL_Data,0,c_RLVL_ID),0),"")) | L22: =IF(J22="","",IF(ISNUMBER(MATCH(J22,Rider_Master[Rider ID],0)),1,0)) | M22: =IF(J22="","",INDEX(Rider_Input[Completed Orders],I22)) | N22: =IF(OR(J22="",K22=""),"",IFERROR(INDEX(RLVL_Data,K22,c_RLVL_Orders),"")) | O22: =IF(J22="","",IF(COUNTIF($J$6:$J$505,J22)>1,1,0)) | P22: =IF(J22="","",IF(K22="","Not found in Paste_RLVL – deductions set to 0; ","")&IF(L22=0,"New rider (not in Rider_Master) – OK, shown as Rider <ID>; ","")&IF(AND(N22<>"",N22<>M22),"Orders differ: FTR "&M22&" vs RLVL "&N22&"; ","")&IF(O22=1,"Duplicate Rider ID; ","")) | Q22: =IF(P22="","",COUNTIF(P$6:P22,"?*"))
B23: Records flagged 'Review Required' in Salary_Calculation | C23: =COUNTIF(Salary_Calculation[Payment Status],"Review Required") -> 0 | D23: =IF(C23=0,"OK","CHECK") -> OK | I23: 18 | J23: =IFERROR(IF(INDEX(Rider_Input[Rider ID],I23)="","",INDEX(Rider_Input[Rider ID],I23)),"") | K23: =IF(J23="","",IFERROR(MATCH(J23,INDEX(RLVL_Data,0,c_RLVL_ID),0),"")) | L23: =IF(J23="","",IF(ISNUMBER(MATCH(J23,Rider_Master[Rider ID],0)),1,0)) | M23: =IF(J23="","",INDEX(Rider_Input[Completed Orders],I23)) | N23: =IF(OR(J23="",K23=""),"",IFERROR(INDEX(RLVL_Data,K23,c_RLVL_Orders),"")) | O23: =IF(J23="","",IF(COUNTIF($J$6:$J$505,J23)>1,1,0)) | P23: =IF(J23="","",IF(K23="","Not found in Paste_RLVL – deductions set to 0; ","")&IF(L23=0,"New rider (not in Rider_Master) – OK, shown as Rider <ID>; ","")&IF(AND(N23<>"",N23<>M23),"Orders differ: FTR "&M23&" vs RLVL "&N23&"; ","")&IF(O23=1,"Duplicate Rider ID; ","")) | Q23: =IF(P23="","",COUNTIF(P$6:P23,"?*"))
B24: New riders not in Rider_Master (information only) | C24: =SUMPRODUCT(($J$6:$J$505<>"")*($L$6:$L$505=0)) -> 0 | D24: =IF(C24=0,"OK","INFO") -> OK | I24: 19 | J24: =IFERROR(IF(INDEX(Rider_Input[Rider ID],I24)="","",INDEX(Rider_Input[Rider ID],I24)),"") | K24: =IF(J24="","",IFERROR(MATCH(J24,INDEX(RLVL_Data,0,c_RLVL_ID),0),"")) | L24: =IF(J24="","",IF(ISNUMBER(MATCH(J24,Rider_Master[Rider ID],0)),1,0)) | M24: =IF(J24="","",INDEX(Rider_Input[Completed Orders],I24)) | N24: =IF(OR(J24="",K24=""),"",IFERROR(INDEX(RLVL_Data,K24,c_RLVL_Orders),"")) | O24: =IF(J24="","",IF(COUNTIF($J$6:$J$505,J24)>1,1,0)) | P24: =IF(J24="","",IF(K24="","Not found in Paste_RLVL – deductions set to 0; ","")&IF(L24=0,"New rider (not in Rider_Master) – OK, shown as Rider <ID>; ","")&IF(AND(N24<>"",N24<>M24),"Orders differ: FTR "&M24&" vs RLVL "&N24&"; ","")&IF(O24=1,"Duplicate Rider ID; ","")) | Q24: =IF(P24="","",COUNTIF(P$6:P24,"?*"))
I25: 20 | J25: =IFERROR(IF(INDEX(Rider_Input[Rider ID],I25)="","",INDEX(Rider_Input[Rider ID],I25)),"") | K25: =IF(J25="","",IFERROR(MATCH(J25,INDEX(RLVL_Data,0,c_RLVL_ID),0),"")) | L25: =IF(J25="","",IF(ISNUMBER(MATCH(J25,Rider_Master[Rider ID],0)),1,0)) | M25: =IF(J25="","",INDEX(Rider_Input[Completed Orders],I25)) | N25: =IF(OR(J25="",K25=""),"",IFERROR(INDEX(RLVL_Data,K25,c_RLVL_Orders),"")) | O25: =IF(J25="","",IF(COUNTIF($J$6:$J$505,J25)>1,1,0)) | P25: =IF(J25="","",IF(K25="","Not found in Paste_RLVL – deductions set to 0; ","")&IF(L25=0,"New rider (not in Rider_Master) – OK, shown as Rider <ID>; ","")&IF(AND(N25<>"",N25<>M25),"Orders differ: FTR "&M25&" vs RLVL "&N25&"; ","")&IF(O25=1,"Duplicate Rider ID; ","")) | Q25: =IF(P25="","",COUNTIF(P$6:P25,"?*"))
B26: Column Mapping – finds each column by header text (use * as wildcard); edit only if the export headers change | I26: 21 | J26: =IFERROR(IF(INDEX(Rider_Input[Rider ID],I26)="","",INDEX(Rider_Input[Rider ID],I26)),"") | K26: =IF(J26="","",IFERROR(MATCH(J26,INDEX(RLVL_Data,0,c_RLVL_ID),0),"")) | L26: =IF(J26="","",IF(ISNUMBER(MATCH(J26,Rider_Master[Rider ID],0)),1,0)) | M26: =IF(J26="","",INDEX(Rider_Input[Completed Orders],I26)) | N26: =IF(OR(J26="",K26=""),"",IFERROR(INDEX(RLVL_Data,K26,c_RLVL_Orders),"")) | O26: =IF(J26="","",IF(COUNTIF($J$6:$J$505,J26)>1,1,0)) | P26: =IF(J26="","",IF(K26="","Not found in Paste_RLVL – deductions set to 0; ","")&IF(L26=0,"New rider (not in Rider_Master) – OK, shown as Rider <ID>; ","")&IF(AND(N26<>"",N26<>M26),"Orders differ: FTR "&M26&" vs RLVL "&N26&"; ","")&IF(O26=1,"Duplicate Rider ID; ","")) | Q26: =IF(P26="","",COUNTIF(P$6:P26,"?*"))
B27: Field | C27: Header contains / text | D27: Sheet | E27: Column # | F27: Found? | I27: 22 | J27: =IFERROR(IF(INDEX(Rider_Input[Rider ID],I27)="","",INDEX(Rider_Input[Rider ID],I27)),"") | K27: =IF(J27="","",IFERROR(MATCH(J27,INDEX(RLVL_Data,0,c_RLVL_ID),0),"")) | L27: =IF(J27="","",IF(ISNUMBER(MATCH(J27,Rider_Master[Rider ID],0)),1,0)) | M27: =IF(J27="","",INDEX(Rider_Input[Completed Orders],I27)) | N27: =IF(OR(J27="",K27=""),"",IFERROR(INDEX(RLVL_Data,K27,c_RLVL_Orders),"")) | O27: =IF(J27="","",IF(COUNTIF($J$6:$J$505,J27)>1,1,0)) | P27: =IF(J27="","",IF(K27="","Not found in Paste_RLVL – deductions set to 0; ","")&IF(L27=0,"New rider (not in Rider_Master) – OK, shown as Rider <ID>; ","")&IF(AND(N27<>"",N27<>M27),"Orders differ: FTR "&M27&" vs RLVL "&N27&"; ","")&IF(O27=1,"Duplicate Rider ID; ","")) | Q27: =IF(P27="","",COUNTIF(P$6:P27,"?*"))
B28: Rider ID (FTR) | C28: *rider_id | D28: Paste_FTR | E28: =IFERROR(MATCH($C28,Paste_FTR!$A$1:$BZ$1,0),"not found") -> 2 | F28: =IF(ISNUMBER(E28),"OK","MISSING") -> OK | I28: 23 | J28: =IFERROR(IF(INDEX(Rider_Input[Rider ID],I28)="","",INDEX(Rider_Input[Rider ID],I28)),"") | K28: =IF(J28="","",IFERROR(MATCH(J28,INDEX(RLVL_Data,0,c_RLVL_ID),0),"")) | L28: =IF(J28="","",IF(ISNUMBER(MATCH(J28,Rider_Master[Rider ID],0)),1,0)) | M28: =IF(J28="","",INDEX(Rider_Input[Completed Orders],I28)) | N28: =IF(OR(J28="",K28=""),"",IFERROR(INDEX(RLVL_Data,K28,c_RLVL_Orders),"")) | O28: =IF(J28="","",IF(COUNTIF($J$6:$J$505,J28)>1,1,0)) | P28: =IF(J28="","",IF(K28="","Not found in Paste_RLVL – deductions set to 0; ","")&IF(L28=0,"New rider (not in Rider_Master) – OK, shown as Rider <ID>; ","")&IF(AND(N28<>"",N28<>M28),"Orders differ: FTR "&M28&" vs RLVL "&N28&"; ","")&IF(O28=1,"Duplicate Rider ID; ","")) | Q28: =IF(P28="","",COUNTIF(P$6:P28,"?*"))
B29: Completed Orders (FTR) | C29: *completed_orders | D29: Paste_FTR | E29: =IFERROR(MATCH($C29,Paste_FTR!$A$1:$BZ$1,0),"not found") -> 8 | F29: =IF(ISNUMBER(E29),"OK","MISSING") -> OK | I29: 24 | J29: =IFERROR(IF(INDEX(Rider_Input[Rider ID],I29)="","",INDEX(Rider_Input[Rider ID],I29)),"") | K29: =IF(J29="","",IFERROR(MATCH(J29,INDEX(RLVL_Data,0,c_RLVL_ID),0),"")) | L29: =IF(J29="","",IF(ISNUMBER(MATCH(J29,Rider_Master[Rider ID],0)),1,0)) | M29: =IF(J29="","",INDEX(Rider_Input[Completed Orders],I29)) | N29: =IF(OR(J29="",K29=""),"",IFERROR(INDEX(RLVL_Data,K29,c_RLVL_Orders),"")) | O29: =IF(J29="","",IF(COUNTIF($J$6:$J$505,J29)>1,1,0)) | P29: =IF(J29="","",IF(K29="","Not found in Paste_RLVL – deductions set to 0; ","")&IF(L29=0,"New rider (not in Rider_Master) – OK, shown as Rider <ID>; ","")&IF(AND(N29<>"",N29<>M29),"Orders differ: FTR "&M29&" vs RLVL "&N29&"; ","")&IF(O29=1,"Duplicate Rider ID; ","")) | Q29: =IF(P29="","",COUNTIF(P$6:P29,"?*"))
B30: Working Days (FTR) | C30: working_days | D30: Paste_FTR | E30: =IFERROR(MATCH($C30,Paste_FTR!$A$1:$BZ$1,0),"not found") -> 12 | F30: =IF(ISNUMBER(E30),"OK","MISSING") -> OK | I30: 25 | J30: =IFERROR(IF(INDEX(Rider_Input[Rider ID],I30)="","",INDEX(Rider_Input[Rider ID],I30)),"") | K30: =IF(J30="","",IFERROR(MATCH(J30,INDEX(RLVL_Data,0,c_RLVL_ID),0),"")) | L30: =IF(J30="","",IF(ISNUMBER(MATCH(J30,Rider_Master[Rider ID],0)),1,0)) | M30: =IF(J30="","",INDEX(Rider_Input[Completed Orders],I30)) | N30: =IF(OR(J30="",K30=""),"",IFERROR(INDEX(RLVL_Data,K30,c_RLVL_Orders),"")) | O30: =IF(J30="","",IF(COUNTIF($J$6:$J$505,J30)>1,1,0)) | P30: =IF(J30="","",IF(K30="","Not found in Paste_RLVL – deductions set to 0; ","")&IF(L30=0,"New rider (not in Rider_Master) – OK, shown as Rider <ID>; ","")&IF(AND(N30<>"",N30<>M30),"Orders differ: FTR "&M30&" vs RLVL "&N30&"; ","")&IF(O30=1,"Duplicate Rider ID; ","")) | Q30: =IF(P30="","",COUNTIF(P$6:P30,"?*"))
B31: Rider ID (RLVL) | C31: *rider_id | D31: Paste_RLVL | E31: =IFERROR(MATCH($C31,Paste_RLVL!$A$1:$BZ$1,0),"not found") -> 1 | F31: =IF(ISNUMBER(E31),"OK","MISSING") -> OK | I31: 26 | J31: =IFERROR(IF(INDEX(Rider_Input[Rider ID],I31)="","",INDEX(Rider_Input[Rider ID],I31)),"") | K31: =IF(J31="","",IFERROR(MATCH(J31,INDEX(RLVL_Data,0,c_RLVL_ID),0),"")) | L31: =IF(J31="","",IF(ISNUMBER(MATCH(J31,Rider_Master[Rider ID],0)),1,0)) | M31: =IF(J31="","",INDEX(Rider_Input[Completed Orders],I31)) | N31: =IF(OR(J31="",K31=""),"",IFERROR(INDEX(RLVL_Data,K31,c_RLVL_Orders),"")) | O31: =IF(J31="","",IF(COUNTIF($J$6:$J$505,J31)>1,1,0)) | P31: =IF(J31="","",IF(K31="","Not found in Paste_RLVL – deductions set to 0; ","")&IF(L31=0,"New rider (not in Rider_Master) – OK, shown as Rider <ID>; ","")&IF(AND(N31<>"",N31<>M31),"Orders differ: FTR "&M31&" vs RLVL "&N31&"; ","")&IF(O31=1,"Duplicate Rider ID; ","")) | Q31: =IF(P31="","",COUNTIF(P$6:P31,"?*"))
B32: Completed Orders (RLVL, cross-check only) | C32: *completed_orders | D32: Paste_RLVL | E32: =IFERROR(MATCH($C32,Paste_RLVL!$A$1:$BZ$1,0),"not found") -> 3 | F32: =IF(ISNUMBER(E32),"OK","MISSING") -> OK | I32: 27 | J32: =IFERROR(IF(INDEX(Rider_Input[Rider ID],I32)="","",INDEX(Rider_Input[Rider ID],I32)),"") | K32: =IF(J32="","",IFERROR(MATCH(J32,INDEX(RLVL_Data,0,c_RLVL_ID),0),"")) | L32: =IF(J32="","",IF(ISNUMBER(MATCH(J32,Rider_Master[Rider ID],0)),1,0)) | M32: =IF(J32="","",INDEX(Rider_Input[Completed Orders],I32)) | N32: =IF(OR(J32="",K32=""),"",IFERROR(INDEX(RLVL_Data,K32,c_RLVL_Orders),"")) | O32: =IF(J32="","",IF(COUNTIF($J$6:$J$505,J32)>1,1,0)) | P32: =IF(J32="","",IF(K32="","Not found in Paste_RLVL – deductions set to 0; ","")&IF(L32=0,"New rider (not in Rider_Master) – OK, shown as Rider <ID>; ","")&IF(AND(N32<>"",N32<>M32),"Orders differ: FTR "&M32&" vs RLVL "&N32&"; ","")&IF(O32=1,"Duplicate Rider ID; ","")) | Q32: =IF(P32="","",COUNTIF(P$6:P32,"?*"))
B33: missed_days_penalty (RLVL) | C33: *missed_days_penalty | D33: Paste_RLVL | E33: =IFERROR(MATCH($C33,Paste_RLVL!$A$1:$BZ$1,0),"not found") -> 12 | F33: =IF(ISNUMBER(E33),"OK","MISSING") -> OK | I33: 28 | J33: =IFERROR(IF(INDEX(Rider_Input[Rider ID],I33)="","",INDEX(Rider_Input[Rider ID],I33)),"") | K33: =IF(J33="","",IFERROR(MATCH(J33,INDEX(RLVL_Data,0,c_RLVL_ID),0),"")) | L33: =IF(J33="","",IF(ISNUMBER(MATCH(J33,Rider_Master[Rider ID],0)),1,0)) | M33: =IF(J33="","",INDEX(Rider_Input[Completed Orders],I33)) | N33: =IF(OR(J33="",K33=""),"",IFERROR(INDEX(RLVL_Data,K33,c_RLVL_Orders),"")) | O33: =IF(J33="","",IF(COUNTIF($J$6:$J$505,J33)>1,1,0)) | P33: =IF(J33="","",IF(K33="","Not found in Paste_RLVL – deductions set to 0; ","")&IF(L33=0,"New rider (not in Rider_Master) – OK, shown as Rider <ID>; ","")&IF(AND(N33<>"",N33<>M33),"Orders differ: FTR "&M33&" vs RLVL "&N33&"; ","")&IF(O33=1,"Duplicate Rider ID; ","")) | Q33: =IF(P33="","",COUNTIF(P$6:P33,"?*"))
B34: Rider Balance (RLVL) | C34: *Rider Balance | D34: Paste_RLVL | E34: =IFERROR(MATCH($C34,Paste_RLVL!$A$1:$BZ$1,0),"not found") -> 16 | F34: =IF(ISNUMBER(E34),"OK","MISSING") -> OK | I34: 29 | J34: =IFERROR(IF(INDEX(Rider_Input[Rider ID],I34)="","",INDEX(Rider_Input[Rider ID],I34)),"") | K34: =IF(J34="","",IFERROR(MATCH(J34,INDEX(RLVL_Data,0,c_RLVL_ID),0),"")) | L34: =IF(J34="","",IF(ISNUMBER(MATCH(J34,Rider_Master[Rider ID],0)),1,0)) | M34: =IF(J34="","",INDEX(Rider_Input[Completed Orders],I34)) | N34: =IF(OR(J34="",K34=""),"",IFERROR(INDEX(RLVL_Data,K34,c_RLVL_Orders),"")) | O34: =IF(J34="","",IF(COUNTIF($J$6:$J$505,J34)>1,1,0)) | P34: =IF(J34="","",IF(K34="","Not found in Paste_RLVL – deductions set to 0; ","")&IF(L34=0,"New rider (not in Rider_Master) – OK, shown as Rider <ID>; ","")&IF(AND(N34<>"",N34<>M34),"Orders differ: FTR "&M34&" vs RLVL "&N34&"; ","")&IF(O34=1,"Duplicate Rider ID; ","")) | Q34: =IF(P34="","",COUNTIF(P$6:P34,"?*"))
B35: stacking_deduction (RLVL) | C35: *stacking_deduction | D35: Paste_RLVL | E35: =IFERROR(MATCH($C35,Paste_RLVL!$A$1:$BZ$1,0),"not found") -> 5 | F35: =IF(ISNUMBER(E35),"OK","MISSING") -> OK | I35: 30 | J35: =IFERROR(IF(INDEX(Rider_Input[Rider ID],I35)="","",INDEX(Rider_Input[Rider ID],I35)),"") | K35: =IF(J35="","",IFERROR(MATCH(J35,INDEX(RLVL_Data,0,c_RLVL_ID),0),"")) | L35: =IF(J35="","",IF(ISNUMBER(MATCH(J35,Rider_Master[Rider ID],0)),1,0)) | M35: =IF(J35="","",INDEX(Rider_Input[Completed Orders],I35)) | N35: =IF(OR(J35="",K35=""),"",IFERROR(INDEX(RLVL_Data,K35,c_RLVL_Orders),"")) | O35: =IF(J35="","",IF(COUNTIF($J$6:$J$505,J35)>1,1,0)) | P35: =IF(J35="","",IF(K35="","Not found in Paste_RLVL – deductions set to 0; ","")&IF(L35=0,"New rider (not in Rider_Master) – OK, shown as Rider <ID>; ","")&IF(AND(N35<>"",N35<>M35),"Orders differ: FTR "&M35&" vs RLVL "&N35&"; ","")&IF(O35=1,"Duplicate Rider ID; ","")) | Q35: =IF(P35="","",COUNTIF(P$6:P35,"?*"))
I36: 31 | J36: =IFERROR(IF(INDEX(Rider_Input[Rider ID],I36)="","",INDEX(Rider_Input[Rider ID],I36)),"") | K36: =IF(J36="","",IFERROR(MATCH(J36,INDEX(RLVL_Data,0,c_RLVL_ID),0),"")) | L36: =IF(J36="","",IF(ISNUMBER(MATCH(J36,Rider_Master[Rider ID],0)),1,0)) | M36: =IF(J36="","",INDEX(Rider_Input[Completed Orders],I36)) | N36: =IF(OR(J36="",K36=""),"",IFERROR(INDEX(RLVL_Data,K36,c_RLVL_Orders),"")) | O36: =IF(J36="","",IF(COUNTIF($J$6:$J$505,J36)>1,1,0)) | P36: =IF(J36="","",IF(K36="","Not found in Paste_RLVL – deductions set to 0; ","")&IF(L36=0,"New rider (not in Rider_Master) – OK, shown as Rider <ID>; ","")&IF(AND(N36<>"",N36<>M36),"Orders differ: FTR "&M36&" vs RLVL "&N36&"; ","")&IF(O36=1,"Duplicate Rider ID; ","")) | Q36: =IF(P36="","",COUNTIF(P$6:P36,"?*"))
I37: 32 | J37: =IFERROR(IF(INDEX(Rider_Input[Rider ID],I37)="","",INDEX(Rider_Input[Rider ID],I37)),"") | K37: =IF(J37="","",IFERROR(MATCH(J37,INDEX(RLVL_Data,0,c_RLVL_ID),0),"")) | L37: =IF(J37="","",IF(ISNUMBER(MATCH(J37,Rider_Master[Rider ID],0)),1,0)) | M37: =IF(J37="","",INDEX(Rider_Input[Completed Orders],I37)) | N37: =IF(OR(J37="",K37=""),"",IFERROR(INDEX(RLVL_Data,K37,c_RLVL_Orders),"")) | O37: =IF(J37="","",IF(COUNTIF($J$6:$J$505,J37)>1,1,0)) | P37: =IF(J37="","",IF(K37="","Not found in Paste_RLVL – deductions set to 0; ","")&IF(L37=0,"New rider (not in Rider_Master) – OK, shown as Rider <ID>; ","")&IF(AND(N37<>"",N37<>M37),"Orders differ: FTR "&M37&" vs RLVL "&N37&"; ","")&IF(O37=1,"Duplicate Rider ID; ","")) | Q37: =IF(P37="","",COUNTIF(P$6:P37,"?*"))
B38: Items to review – first 25 (all riders, full list in helper column P) | I38: 33 | J38: =IFERROR(IF(INDEX(Rider_Input[Rider ID],I38)="","",INDEX(Rider_Input[Rider ID],I38)),"") | K38: =IF(J38="","",IFERROR(MATCH(J38,INDEX(RLVL_Data,0,c_RLVL_ID),0),"")) | L38: =IF(J38="","",IF(ISNUMBER(MATCH(J38,Rider_Master[Rider ID],0)),1,0)) | M38: =IF(J38="","",INDEX(Rider_Input[Completed Orders],I38)) | N38: =IF(OR(J38="",K38=""),"",IFERROR(INDEX(RLVL_Data,K38,c_RLVL_Orders),"")) | O38: =IF(J38="","",IF(COUNTIF($J$6:$J$505,J38)>1,1,0)) | P38: =IF(J38="","",IF(K38="","Not found in Paste_RLVL – deductions set to 0; ","")&IF(L38=0,"New rider (not in Rider_Master) – OK, shown as Rider <ID>; ","")&IF(AND(N38<>"",N38<>M38),"Orders differ: FTR "&M38&" vs RLVL "&N38&"; ","")&IF(O38=1,"Duplicate Rider ID; ","")) | Q38: =IF(P38="","",COUNTIF(P$6:P38,"?*"))
B39: Rider ID | C39: Issue | I39: 34 | J39: =IFERROR(IF(INDEX(Rider_Input[Rider ID],I39)="","",INDEX(Rider_Input[Rider ID],I39)),"") | K39: =IF(J39="","",IFERROR(MATCH(J39,INDEX(RLVL_Data,0,c_RLVL_ID),0),"")) | L39: =IF(J39="","",IF(ISNUMBER(MATCH(J39,Rider_Master[Rider ID],0)),1,0)) | M39: =IF(J39="","",INDEX(Rider_Input[Completed Orders],I39)) | N39: =IF(OR(J39="",K39=""),"",IFERROR(INDEX(RLVL_Data,K39,c_RLVL_Orders),"")) | O39: =IF(J39="","",IF(COUNTIF($J$6:$J$505,J39)>1,1,0)) | P39: =IF(J39="","",IF(K39="","Not found in Paste_RLVL – deductions set to 0; ","")&IF(L39=0,"New rider (not in Rider_Master) – OK, shown as Rider <ID>; ","")&IF(AND(N39<>"",N39<>M39),"Orders differ: FTR "&M39&" vs RLVL "&N39&"; ","")&IF(O39=1,"Duplicate Rider ID; ","")) | Q39: =IF(P39="","",COUNTIF(P$6:P39,"?*"))
B40: =IFERROR(INDEX($J$6:$J$505,MATCH(1,$Q$6:$Q$505,0)),"") | C40: =IFERROR(INDEX($P$6:$P$505,MATCH(1,$Q$6:$Q$505,0)),"") | I40: 35 | J40: =IFERROR(IF(INDEX(Rider_Input[Rider ID],I40)="","",INDEX(Rider_Input[Rider ID],I40)),"") | K40: =IF(J40="","",IFERROR(MATCH(J40,INDEX(RLVL_Data,0,c_RLVL_ID),0),"")) | L40: =IF(J40="","",IF(ISNUMBER(MATCH(J40,Rider_Master[Rider ID],0)),1,0)) | M40: =IF(J40="","",INDEX(Rider_Input[Completed Orders],I40)) | N40: =IF(OR(J40="",K40=""),"",IFERROR(INDEX(RLVL_Data,K40,c_RLVL_Orders),"")) | O40: =IF(J40="","",IF(COUNTIF($J$6:$J$505,J40)>1,1,0)) | P40: =IF(J40="","",IF(K40="","Not found in Paste_RLVL – deductions set to 0; ","")&IF(L40=0,"New rider (not in Rider_Master) – OK, shown as Rider <ID>; ","")&IF(AND(N40<>"",N40<>M40),"Orders differ: FTR "&M40&" vs RLVL "&N40&"; ","")&IF(O40=1,"Duplicate Rider ID; ","")) | Q40: =IF(P40="","",COUNTIF(P$6:P40,"?*"))
B41: =IFERROR(INDEX($J$6:$J$505,MATCH(2,$Q$6:$Q$505,0)),"") | C41: =IFERROR(INDEX($P$6:$P$505,MATCH(2,$Q$6:$Q$505,0)),"") | I41: 36 | J41: =IFERROR(IF(INDEX(Rider_Input[Rider ID],I41)="","",INDEX(Rider_Input[Rider ID],I41)),"") | K41: =IF(J41="","",IFERROR(MATCH(J41,INDEX(RLVL_Data,0,c_RLVL_ID),0),"")) | L41: =IF(J41="","",IF(ISNUMBER(MATCH(J41,Rider_Master[Rider ID],0)),1,0)) | M41: =IF(J41="","",INDEX(Rider_Input[Completed Orders],I41)) | N41: =IF(OR(J41="",K41=""),"",IFERROR(INDEX(RLVL_Data,K41,c_RLVL_Orders),"")) | O41: =IF(J41="","",IF(COUNTIF($J$6:$J$505,J41)>1,1,0)) | P41: =IF(J41="","",IF(K41="","Not found in Paste_RLVL – deductions set to 0; ","")&IF(L41=0,"New rider (not in Rider_Master) – OK, shown as Rider <ID>; ","")&IF(AND(N41<>"",N41<>M41),"Orders differ: FTR "&M41&" vs RLVL "&N41&"; ","")&IF(O41=1,"Duplicate Rider ID; ","")) | Q41: =IF(P41="","",COUNTIF(P$6:P41,"?*"))
...

Sheet Settings
B1: Settings / الإعدادات
A3: Setting / الإعداد | B3: Value / القيمة | C3: Description / الوصف
A4: Order Rate Method | B4: Exact rate | C4: Exact rate = Basic Payment / 450; Fixed rate = 4.44
A5: Default Basic Payment | B5: 2000 | C5: Default SAR basic payment for 450 standard monthly orders (type this into Rider_Input for new riders; used by Example 1 on the dashboard)
A6: Standard Monthly Orders | B6: 450 | C6: Standard monthly target orders for a 30-day month
A7: Standard Month Days | B7: 30 | C7: Denominator for calendar-day adjustment
A8: Fixed Order Rate | B8: 4.44 | C8: Used only when Order Rate Method = Fixed rate
A9: Missing-Order Deduction Rate | B9: 7 | C9: SAR per missing order
A10: Extra-Order Bonus Rate | B10: 10 | C10: SAR per extra order
A11: Company Name | B11: Elite Development | C11: Company name printed on payslips and footers
A12: Company Logo Placeholder | B12: Logo embedded (picture) | C12: The Elite Development logo is embedded as a picture on Payslip_Print, Summary_Dashboard, Instructions, Settings and Monthly_Import. To replace it: right-click the picture → Change Picture.
A13: Salary Month (any date in the month) | B13: 46235 | C13: CHANGE THIS EACH MONTH. Drives Salary Month and Calendar Days for every rider (days in month are calculated automatically).
A14: Status Labels | B14: Meaning
A15: Paid in Full | B15: Payable salary with no deductions reducing the gross salary
A16: Paid After Deductions | B16: Positive final salary after deductions
A17: No Salary – Amount Due from Rider | B17: No payable salary remains and an amount is due from the rider
A18: Review Required | B18: Input is incomplete or violates a validation rule
A19: No Orders | B19: Rider completed zero orders in the month

Sheet Paste_FTR
A1: Contract Name | B1: rider_id | C1: is_active | D1: city_name | E1: rider_vehicle_type | F1: contract_start_date_local | G1: contract_end_date_local | H1: completed_orders | I1: total_monthly_working_hours | J1: working_hours | K1: fully_working_days | L1: working_days | M1: city_monthly_flat_salary | N1: city_payment | O1: basic_rate | P1: declined_penalties_day_logic | Q1: inactive_reason | R1: excused_absence_days | S1: missed_weekends | T1: missed_eom | U1: total_missed_days | V1: missed_days_after_allowance | W1: missed_days_penalty | X1: missed_days_penalty_logic | Y1: segment | Z1: segment_rate | AA1: segment_payment | AB1: manhattan_distance_payable | AC1: distance_payment | BB1: ◀ PASTE AREA: keep the header in row 1, paste the new monthly export from A1. Clear old rows first (select row 2 downward → Delete). Up to 1,000 rows / columns A:BZ are read.
A2: nokhaba_tatweer_ftr | B2: 4849914 | C2: =TRUE() -> TRUE | D2: Qp | E2: car | F2: 46255 | G2: 49907 | H2: 72 | I2: 118.18 | J2: 86.18 | K2: 7 | L2: 8 | N2: 0 | O2: 6 | Q2: Active | R2: 0 | S2: 1 | T2: 1 | U2: 2 | V2: 1 | W2: 0 | X2: Adjusted in basic payment | Y2: E | Z2: 0.75 | AA2: 54 | AB2: 389.044 | AC2: 350.1396
A3: nokhaba_tatweer_ftr | B3: 4849909 | C3: =TRUE() -> TRUE | D3: Qp | E3: car | F3: 46255 | G3: 49907 | H3: 101 | I3: 139.71 | J3: 115.71 | K3: 9 | L3: 11 | N3: 0 | O3: 8 | Q3: Active | R3: 0 | S3: 0 | T3: 1 | U3: 1 | V3: 0 | W3: 0 | X3: No missed days | Y3: E | Z3: 0.75 | AA3: 75.75 | AB3: 572.282 | AC3: 658.1243
A4: nokhaba_tatweer_ftr | B4: 4849222 | C4: =TRUE() -> TRUE | D4: Qp | E4: car | F4: 46254 | G4: 49906 | H4: 105 | I4: 150.94 | J4: 126.94 | K4: 9 | L4: 11 | N4: 0 | O4: 8 | Q4: Active | R4: 0 | S4: 0 | T4: 1 | U4: 1 | V4: 0 | W4: 0 | X4: No missed days | Y4: D | Z4: 1.25 | AA4: 131.25 | AB4: 598.671 | AC4: 688.47165
